<mujoco model="MuJoCo Model">
  <compiler angle="radian"/>

  <visual>
    <scale jointlength="1.6" jointwidth="0.12"/>
  </visual>

  <statistic extent="0.6" center="0 0 0.3"/>

  <default>
    <default class="w1-main"/>
    <default class="w2-main"/>
    <default class="w3-main"/>
    <default class="w4-main"/>
  </default>

  <asset>
    <texture type="skybox" name="//unnamed_texture_0" builtin="flat" rgb1="1 1 1" rgb2="1 1 1" width="512" height="3072"/>
    <texture type="2d" name="groundplane" builtin="checker" mark="edge" rgb1="0.2 0.3 0.4" rgb2="0.1 0.2 0.3" markrgb="0.8 0.8 0.8" width="300" height="300"/>
    <material name="groundplane" texture="groundplane" texuniform="true" texrepeat="5 5" reflectance="0.2"/>
    <mesh name="mesh1" file="meshes\mecanum.stl" scale="0.78 0.78 0.78"/>
    <mesh name="mesh2" file="meshes\mecanum.stl" scale="0.78 0.78 -0.78"/>
  </asset>

  <worldbody>
    <geom name="floor" size="0 0 0.125" type="plane" condim="1" material="groundplane"/>
    <light name="//unnamed_light_0" pos="0 0 3" dir="0 0.624695 -0.780869" directional="true" castshadow="false"/>
    <body name="box" pos="0 0 0.065">
      <joint name="slidex" pos="0 0 0" axis="1 0 0" type="slide"/>
      <joint name="slidey" pos="0 0 0" axis="0 1 0" type="slide"/>
      <joint name="slidez" pos="0 0 0" axis="0 0 1" type="slide"/>
      <joint name="phi" pos="0 0 0" axis="0 0 1"/>
      <geom size="0.1 0.2 0.025" type="box" rgba="0.2 0.4 0.2 1"/>
      <site name="box_center" pos="0 0 0"/>
      <site pos="0.12 0.16 -0.025" quat="0.707107 0 0 -0.707107"/>
      <site pos="-0.12 0.16 -0.025" quat="0.707107 0 0 -0.707107"/>
      <site pos="-0.12 -0.16 -0.025" quat="0.707107 0 0 -0.707107"/>
      <site pos="0.12 -0.16 -0.025" quat="0.707107 0 0 -0.707107"/>
      <body name="w1-hub" pos="0.12 0.16 -0.025" quat="0.707107 0 0 -0.707107">
        <joint name="w1-hub" pos="0 0 0" axis="0 1 0"/>
        <geom size="0.036 0.02" quat="0.707107 0.707107 0 0" type="cylinder" conaffinity="0" group="1"/>
        <geom quat="0.707107 0.707107 0 0" type="mesh" group="2" rgba="0.2 0.2 0.2 1" mesh="mesh1"/>
        <body name="w1-roller_0" pos="0.00682843 0 0.00282843">
          <joint name="w1-slip_0" pos="0 0 0" axis="-0.270598 0.707107 0.653281" limited="false" actuatorfrclimited="false"/>
          <geom size="0.032" group="1"/>
        </body>
        <body name="w1-roller_1" pos="0.00282843 0 0.00682843">
          <joint name="w1-slip_1" pos="0 0 0" axis="-0.653281 0.707107 0.270598" limited="false" actuatorfrclimited="false"/>
          <geom size="0.032" group="1"/>
        </body>
        <body name="w1-roller_2" pos="-0.00282843 0 0.00682843">
          <joint name="w1-slip_2" pos="0 0 0" axis="-0.653281 0.707107 -0.270598" limited="false" actuatorfrclimited="false"/>
          <geom size="0.032" group="1"/>
        </body>
        <body name="w1-roller_3" pos="-0.00682843 0 0.00282843">
          <joint name="w1-slip_3" pos="0 0 0" axis="-0.270598 0.707107 -0.653281" limited="false" actuatorfrclimited="false"/>
          <geom size="0.032" group="1"/>
        </body>
        <body name="w1-roller_4" pos="-0.00682843 0 -0.00282843">
          <joint name="w1-slip_4" pos="0 0 0" axis="0.270598 0.707107 -0.653281" limited="false" actuatorfrclimited="false"/>
          <geom size="0.032" group="1"/>
        </body>
        <body name="w1-roller_5" pos="-0.00282843 0 -0.00682843">
          <joint name="w1-slip_5" pos="0 0 0" axis="0.653281 0.707107 -0.270598" limited="false" actuatorfrclimited="false"/>
          <geom size="0.032" group="1"/>
        </body>
        <body name="w1-roller_6" pos="0.00282843 0 -0.00682843">
          <joint name="w1-slip_6" pos="0 0 0" axis="0.653281 0.707107 0.270598" limited="false" actuatorfrclimited="false"/>
          <geom size="0.032" group="1"/>
        </body>
        <body name="w1-roller_7" pos="0.00682843 0 -0.00282843">
          <joint name="w1-slip_7" pos="0 0 0" axis="0.270598 0.707107 0.653281" limited="false" actuatorfrclimited="false"/>
          <geom size="0.032" group="1"/>
        </body>
      </body>
      <body name="w2-hub" pos="-0.12 0.16 -0.025" quat="0.707107 0 0 -0.707107">
        <joint name="w2-hub" pos="0 0 0" axis="0 1 0"/>
        <geom size="0.036 0.02" quat="0.707107 0.707107 0 0" type="cylinder" conaffinity="0" group="1"/>
        <geom quat="0.707107 0.707107 0 0" type="mesh" group="2" rgba="0.2 0.2 0.2 1" mesh="mesh2"/>
        <body name="w2-roller_0" pos="0.00682843 0 -0.00282843">
          <joint name="w2-slip_0" pos="0 0 0" axis="-0.270598 0.707107 -0.653281" limited="false" actuatorfrclimited="false"/>
          <geom size="0.032" group="1"/>
        </body>
        <body name="w2-roller_1" pos="0.00682843 0 0.00282843">
          <joint name="w2-slip_1" pos="0 0 0" axis="0.270598 0.707107 -0.653281" limited="false" actuatorfrclimited="false"/>
          <geom size="0.032" group="1"/>
        </body>
        <body name="w2-roller_2" pos="0.00282843 0 0.00682843">
          <joint name="w2-slip_2" pos="0 0 0" axis="0.653281 0.707107 -0.270598" limited="false" actuatorfrclimited="false"/>
          <geom size="0.032" group="1"/>
        </body>
        <body name="w2-roller_3" pos="-0.00282843 0 0.00682843">
          <joint name="w2-slip_3" pos="0 0 0" axis="0.653281 0.707107 0.270598" limited="false" actuatorfrclimited="false"/>
          <geom size="0.032" group="1"/>
        </body>
        <body name="w2-roller_4" pos="-0.00682843 0 0.00282843">
          <joint name="w2-slip_4" pos="0 0 0" axis="0.270598 0.707107 0.653281" limited="false" actuatorfrclimited="false"/>
          <geom size="0.032" group="1"/>
        </body>
        <body name="w2-roller_5" pos="-0.00682843 0 -0.00282843">
          <joint name="w2-slip_5" pos="0 0 0" axis="-0.270598 0.707107 0.653281" limited="false" actuatorfrclimited="false"/>
          <geom size="0.032" group="1"/>
        </body>
        <body name="w2-roller_6" pos="-0.00282843 0 -0.00682843">
          <joint name="w2-slip_6" pos="0 0 0" axis="-0.653281 0.707107 0.270598" limited="false" actuatorfrclimited="false"/>
          <geom size="0.032" group="1"/>
        </body>
        <body name="w2-roller_7" pos="0.00282843 0 -0.00682843">
          <joint name="w2-slip_7" pos="0 0 0" axis="-0.653281 0.707107 -0.270598" limited="false" actuatorfrclimited="false"/>
          <geom size="0.032" group="1"/>
        </body>
      </body>
      <body name="w3-hub" pos="-0.12 -0.16 -0.025" quat="0.707107 0 0 -0.707107">
        <joint name="w3-hub" pos="0 0 0" axis="0 1 0"/>
        <geom size="0.036 0.02" quat="0.707107 0.707107 0 0" type="cylinder" conaffinity="0" group="1"/>
        <geom quat="0.707107 0.707107 0 0" type="mesh" group="2" rgba="0.2 0.2 0.2 1" mesh="mesh1"/>
        <body name="w3-roller_0" pos="0.00682843 0 0.00282843">
          <joint name="w3-slip_0" pos="0 0 0" axis="-0.270598 0.707107 0.653281" limited="false" actuatorfrclimited="false"/>
          <geom size="0.032" group="1"/>
        </body>
        <body name="w3-roller_1" pos="0.00282843 0 0.00682843">
          <joint name="w3-slip_1" pos="0 0 0" axis="-0.653281 0.707107 0.270598" limited="false" actuatorfrclimited="false"/>
          <geom size="0.032" group="1"/>
        </body>
        <body name="w3-roller_2" pos="-0.00282843 0 0.00682843">
          <joint name="w3-slip_2" pos="0 0 0" axis="-0.653281 0.707107 -0.270598" limited="false" actuatorfrclimited="false"/>
          <geom size="0.032" group="1"/>
        </body>
        <body name="w3-roller_3" pos="-0.00682843 0 0.00282843">
          <joint name="w3-slip_3" pos="0 0 0" axis="-0.270598 0.707107 -0.653281" limited="false" actuatorfrclimited="false"/>
          <geom size="0.032" group="1"/>
        </body>
        <body name="w3-roller_4" pos="-0.00682843 0 -0.00282843">
          <joint name="w3-slip_4" pos="0 0 0" axis="0.270598 0.707107 -0.653281" limited="false" actuatorfrclimited="false"/>
          <geom size="0.032" group="1"/>
        </body>
        <body name="w3-roller_5" pos="-0.00282843 0 -0.00682843">
          <joint name="w3-slip_5" pos="0 0 0" axis="0.653281 0.707107 -0.270598" limited="false" actuatorfrclimited="false"/>
          <geom size="0.032" group="1"/>
        </body>
        <body name="w3-roller_6" pos="0.00282843 0 -0.00682843">
          <joint name="w3-slip_6" pos="0 0 0" axis="0.653281 0.707107 0.270598" limited="false" actuatorfrclimited="false"/>
          <geom size="0.032" group="1"/>
        </body>
        <body name="w3-roller_7" pos="0.00682843 0 -0.00282843">
          <joint name="w3-slip_7" pos="0 0 0" axis="0.270598 0.707107 0.653281" limited="false" actuatorfrclimited="false"/>
          <geom size="0.032" group="1"/>
        </body>
      </body>
      <body name="w4-hub" pos="0.12 -0.16 -0.025" quat="0.707107 0 0 -0.707107">
        <joint name="w4-hub" pos="0 0 0" axis="0 1 0"/>
        <geom size="0.036 0.02" quat="0.707107 0.707107 0 0" type="cylinder" conaffinity="0" group="1"/>
        <geom quat="0.707107 0.707107 0 0" type="mesh" group="2" rgba="0.2 0.2 0.2 1" mesh="mesh2"/>
        <body name="w4-roller_0" pos="0.00682843 0 -0.00282843">
          <joint name="w4-slip_0" pos="0 0 0" axis="-0.270598 0.707107 -0.653281" limited="false" actuatorfrclimited="false"/>
          <geom size="0.032" group="1"/>
        </body>
        <body name="w4-roller_1" pos="0.00682843 0 0.00282843">
          <joint name="w4-slip_1" pos="0 0 0" axis="0.270598 0.707107 -0.653281" limited="false" actuatorfrclimited="false"/>
          <geom size="0.032" group="1"/>
        </body>
        <body name="w4-roller_2" pos="0.00282843 0 0.00682843">
          <joint name="w4-slip_2" pos="0 0 0" axis="0.653281 0.707107 -0.270598" limited="false" actuatorfrclimited="false"/>
          <geom size="0.032" group="1"/>
        </body>
        <body name="w4-roller_3" pos="-0.00282843 0 0.00682843">
          <joint name="w4-slip_3" pos="0 0 0" axis="0.653281 0.707107 0.270598" limited="false" actuatorfrclimited="false"/>
          <geom size="0.032" group="1"/>
        </body>
        <body name="w4-roller_4" pos="-0.00682843 0 0.00282843">
          <joint name="w4-slip_4" pos="0 0 0" axis="0.270598 0.707107 0.653281" limited="false" actuatorfrclimited="false"/>
          <geom size="0.032" group="1"/>
        </body>
        <body name="w4-roller_5" pos="-0.00682843 0 -0.00282843">
          <joint name="w4-slip_5" pos="0 0 0" axis="-0.270598 0.707107 0.653281" limited="false" actuatorfrclimited="false"/>
          <geom size="0.032" group="1"/>
        </body>
        <body name="w4-roller_6" pos="-0.00282843 0 -0.00682843">
          <joint name="w4-slip_6" pos="0 0 0" axis="-0.653281 0.707107 0.270598" limited="false" actuatorfrclimited="false"/>
          <geom size="0.032" group="1"/>
        </body>
        <body name="w4-roller_7" pos="0.00282843 0 -0.00682843">
          <joint name="w4-slip_7" pos="0 0 0" axis="-0.653281 0.707107 -0.270598" limited="false" actuatorfrclimited="false"/>
          <geom size="0.032" group="1"/>
        </body>
      </body>
    </body>
  </worldbody>

  <contact>
    <exclude name="exclude_world_w1-hub" body1="world" body2="w1-hub"/>
    <exclude name="exclude_w2-hub_world" body1="world" body2="w2-hub"/>
    <exclude name="exclude_w3-hub_world" body1="world" body2="w3-hub"/>
    <exclude name="exclude_w4-hub_world" body1="world" body2="w4-hub"/>
    <exclude name="exclude_w1-hub_box" body1="box" body2="w1-hub"/>
    <exclude name="exclude_w1-roller_0_box" body1="box" body2="w1-roller_0"/>
    <exclude name="exclude_w1-roller_1_box" body1="box" body2="w1-roller_1"/>
    <exclude name="exclude_w1-roller_2_box" body1="box" body2="w1-roller_2"/>
    <exclude name="exclude_w1-roller_3_box" body1="box" body2="w1-roller_3"/>
    <exclude name="exclude_w1-roller_4_box" body1="box" body2="w1-roller_4"/>
    <exclude name="exclude_w1-roller_5_box" body1="box" body2="w1-roller_5"/>
    <exclude name="exclude_w1-roller_6_box" body1="box" body2="w1-roller_6"/>
    <exclude name="exclude_w1-roller_7_box" body1="box" body2="w1-roller_7"/>
    <exclude name="exclude_w2-hub_box" body1="box" body2="w2-hub"/>
    <exclude name="exclude_w2-roller_0_box" body1="box" body2="w2-roller_0"/>
    <exclude name="exclude_w2-roller_1_box" body1="box" body2="w2-roller_1"/>
    <exclude name="exclude_w2-roller_2_box" body1="box" body2="w2-roller_2"/>
    <exclude name="exclude_w2-roller_3_box" body1="box" body2="w2-roller_3"/>
    <exclude name="exclude_w2-roller_4_box" body1="box" body2="w2-roller_4"/>
    <exclude name="exclude_w2-roller_5_box" body1="box" body2="w2-roller_5"/>
    <exclude name="exclude_w2-roller_6_box" body1="box" body2="w2-roller_6"/>
    <exclude name="exclude_w2-roller_7_box" body1="box" body2="w2-roller_7"/>
    <exclude name="exclude_w3-hub_box" body1="box" body2="w3-hub"/>
    <exclude name="exclude_w3-roller_0_box" body1="box" body2="w3-roller_0"/>
    <exclude name="exclude_w3-roller_1_box" body1="box" body2="w3-roller_1"/>
    <exclude name="exclude_w3-roller_2_box" body1="box" body2="w3-roller_2"/>
    <exclude name="exclude_w3-roller_3_box" body1="box" body2="w3-roller_3"/>
    <exclude name="exclude_w3-roller_4_box" body1="box" body2="w3-roller_4"/>
    <exclude name="exclude_w3-roller_5_box" body1="box" body2="w3-roller_5"/>
    <exclude name="exclude_w3-roller_6_box" body1="box" body2="w3-roller_6"/>
    <exclude name="exclude_w3-roller_7_box" body1="box" body2="w3-roller_7"/>
    <exclude name="exclude_w4-hub_box" body1="box" body2="w4-hub"/>
    <exclude name="exclude_w4-roller_0_box" body1="box" body2="w4-roller_0"/>
    <exclude name="exclude_w4-roller_1_box" body1="box" body2="w4-roller_1"/>
    <exclude name="exclude_w4-roller_2_box" body1="box" body2="w4-roller_2"/>
    <exclude name="exclude_w4-roller_3_box" body1="box" body2="w4-roller_3"/>
    <exclude name="exclude_w4-roller_4_box" body1="box" body2="w4-roller_4"/>
    <exclude name="exclude_w4-roller_5_box" body1="box" body2="w4-roller_5"/>
    <exclude name="exclude_w4-roller_6_box" body1="box" body2="w4-roller_6"/>
    <exclude name="exclude_w4-roller_7_box" body1="box" body2="w4-roller_7"/>
    <exclude name="exclude_w1-hub_w1-roller_0" body1="w1-hub" body2="w1-roller_0"/>
    <exclude name="exclude_w1-roller_1_w1-hub" body1="w1-hub" body2="w1-roller_1"/>
    <exclude name="exclude_w1-roller_2_w1-hub" body1="w1-hub" body2="w1-roller_2"/>
    <exclude name="exclude_w1-hub_w1-roller_3" body1="w1-hub" body2="w1-roller_3"/>
    <exclude name="exclude_w1-hub_w1-roller_4" body1="w1-hub" body2="w1-roller_4"/>
    <exclude name="exclude_w1-hub_w1-roller_5" body1="w1-hub" body2="w1-roller_5"/>
    <exclude name="exclude_w1-hub_w1-roller_6" body1="w1-hub" body2="w1-roller_6"/>
    <exclude name="exclude_w1-roller_7_w1-hub" body1="w1-hub" body2="w1-roller_7"/>
    <exclude name="exclude_w1-roller_1_w1-roller_0" body1="w1-roller_0" body2="w1-roller_1"/>
    <exclude name="exclude_w1-roller_2_w1-roller_0" body1="w1-roller_0" body2="w1-roller_2"/>
    <exclude name="exclude_w1-roller_0_w1-roller_3" body1="w1-roller_0" body2="w1-roller_3"/>
    <exclude name="exclude_w1-roller_0_w1-roller_4" body1="w1-roller_0" body2="w1-roller_4"/>
    <exclude name="exclude_w1-roller_0_w1-roller_5" body1="w1-roller_0" body2="w1-roller_5"/>
    <exclude name="exclude_w1-roller_0_w1-roller_6" body1="w1-roller_0" body2="w1-roller_6"/>
    <exclude name="exclude_w1-roller_7_w1-roller_0" body1="w1-roller_0" body2="w1-roller_7"/>
    <exclude name="exclude_w1-roller_2_w1-roller_1" body1="w1-roller_1" body2="w1-roller_2"/>
    <exclude name="exclude_w1-roller_1_w1-roller_3" body1="w1-roller_1" body2="w1-roller_3"/>
    <exclude name="exclude_w1-roller_1_w1-roller_4" body1="w1-roller_1" body2="w1-roller_4"/>
    <exclude name="exclude_w1-roller_1_w1-roller_5" body1="w1-roller_1" body2="w1-roller_5"/>
    <exclude name="exclude_w1-roller_1_w1-roller_6" body1="w1-roller_1" body2="w1-roller_6"/>
    <exclude name="exclude_w1-roller_7_w1-roller_1" body1="w1-roller_1" body2="w1-roller_7"/>
    <exclude name="exclude_w1-roller_2_w1-roller_3" body1="w1-roller_2" body2="w1-roller_3"/>
    <exclude name="exclude_w1-roller_2_w1-roller_4" body1="w1-roller_2" body2="w1-roller_4"/>
    <exclude name="exclude_w1-roller_2_w1-roller_5" body1="w1-roller_2" body2="w1-roller_5"/>
    <exclude name="exclude_w1-roller_2_w1-roller_6" body1="w1-roller_2" body2="w1-roller_6"/>
    <exclude name="exclude_w1-roller_2_w1-roller_7" body1="w1-roller_2" body2="w1-roller_7"/>
    <exclude name="exclude_w1-roller_3_w1-roller_4" body1="w1-roller_3" body2="w1-roller_4"/>
    <exclude name="exclude_w1-roller_3_w1-roller_5" body1="w1-roller_3" body2="w1-roller_5"/>
    <exclude name="exclude_w1-roller_6_w1-roller_3" body1="w1-roller_3" body2="w1-roller_6"/>
    <exclude name="exclude_w1-roller_7_w1-roller_3" body1="w1-roller_3" body2="w1-roller_7"/>
    <exclude name="exclude_w1-roller_4_w1-roller_5" body1="w1-roller_4" body2="w1-roller_5"/>
    <exclude name="exclude_w1-roller_6_w1-roller_4" body1="w1-roller_4" body2="w1-roller_6"/>
    <exclude name="exclude_w1-roller_7_w1-roller_4" body1="w1-roller_4" body2="w1-roller_7"/>
    <exclude name="exclude_w1-roller_6_w1-roller_5" body1="w1-roller_5" body2="w1-roller_6"/>
    <exclude name="exclude_w1-roller_7_w1-roller_5" body1="w1-roller_5" body2="w1-roller_7"/>
    <exclude name="exclude_w1-roller_7_w1-roller_6" body1="w1-roller_6" body2="w1-roller_7"/>
    <exclude name="exclude_w2-hub_w2-roller_0" body1="w2-hub" body2="w2-roller_0"/>
    <exclude name="exclude_w2-roller_1_w2-hub" body1="w2-hub" body2="w2-roller_1"/>
    <exclude name="exclude_w2-roller_2_w2-hub" body1="w2-hub" body2="w2-roller_2"/>
    <exclude name="exclude_w2-roller_3_w2-hub" body1="w2-hub" body2="w2-roller_3"/>
    <exclude name="exclude_w2-hub_w2-roller_4" body1="w2-hub" body2="w2-roller_4"/>
    <exclude name="exclude_w2-hub_w2-roller_5" body1="w2-hub" body2="w2-roller_5"/>
    <exclude name="exclude_w2-roller_6_w2-hub" body1="w2-hub" body2="w2-roller_6"/>
    <exclude name="exclude_w2-roller_7_w2-hub" body1="w2-hub" body2="w2-roller_7"/>
    <exclude name="exclude_w2-roller_1_w2-roller_0" body1="w2-roller_0" body2="w2-roller_1"/>
    <exclude name="exclude_w2-roller_2_w2-roller_0" body1="w2-roller_0" body2="w2-roller_2"/>
    <exclude name="exclude_w2-roller_3_w2-roller_0" body1="w2-roller_0" body2="w2-roller_3"/>
    <exclude name="exclude_w2-roller_4_w2-roller_0" body1="w2-roller_0" body2="w2-roller_4"/>
    <exclude name="exclude_w2-roller_0_w2-roller_5" body1="w2-roller_0" body2="w2-roller_5"/>
    <exclude name="exclude_w2-roller_6_w2-roller_0" body1="w2-roller_0" body2="w2-roller_6"/>
    <exclude name="exclude_w2-roller_7_w2-roller_0" body1="w2-roller_0" body2="w2-roller_7"/>
    <exclude name="exclude_w2-roller_1_w2-roller_2" body1="w2-roller_1" body2="w2-roller_2"/>
    <exclude name="exclude_w2-roller_1_w2-roller_3" body1="w2-roller_1" body2="w2-roller_3"/>
    <exclude name="exclude_w2-roller_1_w2-roller_4" body1="w2-roller_1" body2="w2-roller_4"/>
    <exclude name="exclude_w2-roller_1_w2-roller_5" body1="w2-roller_1" body2="w2-roller_5"/>
    <exclude name="exclude_w2-roller_1_w2-roller_6" body1="w2-roller_1" body2="w2-roller_6"/>
    <exclude name="exclude_w2-roller_7_w2-roller_1" body1="w2-roller_1" body2="w2-roller_7"/>
    <exclude name="exclude_w2-roller_2_w2-roller_3" body1="w2-roller_2" body2="w2-roller_3"/>
    <exclude name="exclude_w2-roller_2_w2-roller_4" body1="w2-roller_2" body2="w2-roller_4"/>
    <exclude name="exclude_w2-roller_2_w2-roller_5" body1="w2-roller_2" body2="w2-roller_5"/>
    <exclude name="exclude_w2-roller_2_w2-roller_6" body1="w2-roller_2" body2="w2-roller_6"/>
    <exclude name="exclude_w2-roller_7_w2-roller_2" body1="w2-roller_2" body2="w2-roller_7"/>
    <exclude name="exclude_w2-roller_3_w2-roller_4" body1="w2-roller_3" body2="w2-roller_4"/>
    <exclude name="exclude_w2-roller_3_w2-roller_5" body1="w2-roller_3" body2="w2-roller_5"/>
    <exclude name="exclude_w2-roller_6_w2-roller_3" body1="w2-roller_3" body2="w2-roller_6"/>
    <exclude name="exclude_w2-roller_7_w2-roller_3" body1="w2-roller_3" body2="w2-roller_7"/>
    <exclude name="exclude_w2-roller_4_w2-roller_5" body1="w2-roller_4" body2="w2-roller_5"/>
    <exclude name="exclude_w2-roller_6_w2-roller_4" body1="w2-roller_4" body2="w2-roller_6"/>
    <exclude name="exclude_w2-roller_7_w2-roller_4" body1="w2-roller_4" body2="w2-roller_7"/>
    <exclude name="exclude_w2-roller_6_w2-roller_5" body1="w2-roller_5" body2="w2-roller_6"/>
    <exclude name="exclude_w2-roller_7_w2-roller_5" body1="w2-roller_5" body2="w2-roller_7"/>
    <exclude name="exclude_w2-roller_7_w2-roller_6" body1="w2-roller_6" body2="w2-roller_7"/>
    <exclude name="exclude_w3-hub_w3-roller_0" body1="w3-hub" body2="w3-roller_0"/>
    <exclude name="exclude_w3-roller_1_w3-hub" body1="w3-hub" body2="w3-roller_1"/>
    <exclude name="exclude_w3-roller_2_w3-hub" body1="w3-hub" body2="w3-roller_2"/>
    <exclude name="exclude_w3-roller_3_w3-hub" body1="w3-hub" body2="w3-roller_3"/>
    <exclude name="exclude_w3-hub_w3-roller_4" body1="w3-hub" body2="w3-roller_4"/>
    <exclude name="exclude_w3-hub_w3-roller_5" body1="w3-hub" body2="w3-roller_5"/>
    <exclude name="exclude_w3-roller_6_w3-hub" body1="w3-hub" body2="w3-roller_6"/>
    <exclude name="exclude_w3-roller_7_w3-hub" body1="w3-hub" body2="w3-roller_7"/>
    <exclude name="exclude_w3-roller_1_w3-roller_0" body1="w3-roller_0" body2="w3-roller_1"/>
    <exclude name="exclude_w3-roller_2_w3-roller_0" body1="w3-roller_0" body2="w3-roller_2"/>
    <exclude name="exclude_w3-roller_3_w3-roller_0" body1="w3-roller_0" body2="w3-roller_3"/>
    <exclude name="exclude_w3-roller_4_w3-roller_0" body1="w3-roller_0" body2="w3-roller_4"/>
    <exclude name="exclude_w3-roller_0_w3-roller_5" body1="w3-roller_0" body2="w3-roller_5"/>
    <exclude name="exclude_w3-roller_6_w3-roller_0" body1="w3-roller_0" body2="w3-roller_6"/>
    <exclude name="exclude_w3-roller_7_w3-roller_0" body1="w3-roller_0" body2="w3-roller_7"/>
    <exclude name="exclude_w3-roller_1_w3-roller_2" body1="w3-roller_1" body2="w3-roller_2"/>
    <exclude name="exclude_w3-roller_1_w3-roller_3" body1="w3-roller_1" body2="w3-roller_3"/>
    <exclude name="exclude_w3-roller_1_w3-roller_4" body1="w3-roller_1" body2="w3-roller_4"/>
    <exclude name="exclude_w3-roller_1_w3-roller_5" body1="w3-roller_1" body2="w3-roller_5"/>
    <exclude name="exclude_w3-roller_1_w3-roller_6" body1="w3-roller_1" body2="w3-roller_6"/>
    <exclude name="exclude_w3-roller_7_w3-roller_1" body1="w3-roller_1" body2="w3-roller_7"/>
    <exclude name="exclude_w3-roller_2_w3-roller_3" body1="w3-roller_2" body2="w3-roller_3"/>
    <exclude name="exclude_w3-roller_2_w3-roller_4" body1="w3-roller_2" body2="w3-roller_4"/>
    <exclude name="exclude_w3-roller_2_w3-roller_5" body1="w3-roller_2" body2="w3-roller_5"/>
    <exclude name="exclude_w3-roller_2_w3-roller_6" body1="w3-roller_2" body2="w3-roller_6"/>
    <exclude name="exclude_w3-roller_7_w3-roller_2" body1="w3-roller_2" body2="w3-roller_7"/>
    <exclude name="exclude_w3-roller_3_w3-roller_4" body1="w3-roller_3" body2="w3-roller_4"/>
    <exclude name="exclude_w3-roller_3_w3-roller_5" body1="w3-roller_3" body2="w3-roller_5"/>
    <exclude name="exclude_w3-roller_6_w3-roller_3" body1="w3-roller_3" body2="w3-roller_6"/>
    <exclude name="exclude_w3-roller_7_w3-roller_3" body1="w3-roller_3" body2="w3-roller_7"/>
    <exclude name="exclude_w3-roller_4_w3-roller_5" body1="w3-roller_4" body2="w3-roller_5"/>
    <exclude name="exclude_w3-roller_6_w3-roller_4" body1="w3-roller_4" body2="w3-roller_6"/>
    <exclude name="exclude_w3-roller_7_w3-roller_4" body1="w3-roller_4" body2="w3-roller_7"/>
    <exclude name="exclude_w3-roller_6_w3-roller_5" body1="w3-roller_5" body2="w3-roller_6"/>
    <exclude name="exclude_w3-roller_7_w3-roller_5" body1="w3-roller_5" body2="w3-roller_7"/>
    <exclude name="exclude_w3-roller_7_w3-roller_6" body1="w3-roller_6" body2="w3-roller_7"/>
    <exclude name="exclude_w4-roller_0_w4-hub" body1="w4-hub" body2="w4-roller_0"/>
    <exclude name="exclude_w4-roller_1_w4-hub" body1="w4-hub" body2="w4-roller_1"/>
    <exclude name="exclude_w4-roller_2_w4-hub" body1="w4-hub" body2="w4-roller_2"/>
    <exclude name="exclude_w4-roller_3_w4-hub" body1="w4-hub" body2="w4-roller_3"/>
    <exclude name="exclude_w4-roller_4_w4-hub" body1="w4-hub" body2="w4-roller_4"/>
    <exclude name="exclude_w4-hub_w4-roller_5" body1="w4-hub" body2="w4-roller_5"/>
    <exclude name="exclude_w4-roller_6_w4-hub" body1="w4-hub" body2="w4-roller_6"/>
    <exclude name="exclude_w4-roller_7_w4-hub" body1="w4-hub" body2="w4-roller_7"/>
    <exclude name="exclude_w4-roller_1_w4-roller_0" body1="w4-roller_0" body2="w4-roller_1"/>
    <exclude name="exclude_w4-roller_2_w4-roller_0" body1="w4-roller_0" body2="w4-roller_2"/>
    <exclude name="exclude_w4-roller_3_w4-roller_0" body1="w4-roller_0" body2="w4-roller_3"/>
    <exclude name="exclude_w4-roller_4_w4-roller_0" body1="w4-roller_0" body2="w4-roller_4"/>
    <exclude name="exclude_w4-roller_0_w4-roller_5" body1="w4-roller_0" body2="w4-roller_5"/>
    <exclude name="exclude_w4-roller_6_w4-roller_0" body1="w4-roller_0" body2="w4-roller_6"/>
    <exclude name="exclude_w4-roller_7_w4-roller_0" body1="w4-roller_0" body2="w4-roller_7"/>
    <exclude name="exclude_w4-roller_1_w4-roller_2" body1="w4-roller_1" body2="w4-roller_2"/>
    <exclude name="exclude_w4-roller_1_w4-roller_3" body1="w4-roller_1" body2="w4-roller_3"/>
    <exclude name="exclude_w4-roller_1_w4-roller_4" body1="w4-roller_1" body2="w4-roller_4"/>
    <exclude name="exclude_w4-roller_1_w4-roller_5" body1="w4-roller_1" body2="w4-roller_5"/>
    <exclude name="exclude_w4-roller_1_w4-roller_6" body1="w4-roller_1" body2="w4-roller_6"/>
    <exclude name="exclude_w4-roller_7_w4-roller_1" body1="w4-roller_1" body2="w4-roller_7"/>
    <exclude name="exclude_w4-roller_2_w4-roller_3" body1="w4-roller_2" body2="w4-roller_3"/>
    <exclude name="exclude_w4-roller_2_w4-roller_4" body1="w4-roller_2" body2="w4-roller_4"/>
    <exclude name="exclude_w4-roller_2_w4-roller_5" body1="w4-roller_2" body2="w4-roller_5"/>
    <exclude name="exclude_w4-roller_2_w4-roller_6" body1="w4-roller_2" body2="w4-roller_6"/>
    <exclude name="exclude_w4-roller_7_w4-roller_2" body1="w4-roller_2" body2="w4-roller_7"/>
    <exclude name="exclude_w4-roller_3_w4-roller_4" body1="w4-roller_3" body2="w4-roller_4"/>
    <exclude name="exclude_w4-roller_3_w4-roller_5" body1="w4-roller_3" body2="w4-roller_5"/>
    <exclude name="exclude_w4-roller_3_w4-roller_6" body1="w4-roller_3" body2="w4-roller_6"/>
    <exclude name="exclude_w4-roller_7_w4-roller_3" body1="w4-roller_3" body2="w4-roller_7"/>
    <exclude name="exclude_w4-roller_4_w4-roller_5" body1="w4-roller_4" body2="w4-roller_5"/>
    <exclude name="exclude_w4-roller_6_w4-roller_4" body1="w4-roller_4" body2="w4-roller_6"/>
    <exclude name="exclude_w4-roller_7_w4-roller_4" body1="w4-roller_4" body2="w4-roller_7"/>
    <exclude name="exclude_w4-roller_6_w4-roller_5" body1="w4-roller_5" body2="w4-roller_6"/>
    <exclude name="exclude_w4-roller_7_w4-roller_5" body1="w4-roller_5" body2="w4-roller_7"/>
    <exclude name="exclude_w4-roller_7_w4-roller_6" body1="w4-roller_6" body2="w4-roller_7"/>
  </contact>

  <actuator>
    <general name="torque1" joint="w1-hub" ctrllimited="false"/>
    <general name="torque2" joint="w2-hub" ctrllimited="false"/>
    <general name="torque3" joint="w3-hub" ctrllimited="false"/>
    <general name="torque4" joint="w4-hub" ctrllimited="false"/>
  </actuator>

  <sensor>
    <framepos objtype="site" objname="box_center" name="pos_c"/>
    <framelinvel objtype="site" objname="box_center" name="vel_c"/>
    <frameangvel objtype="site" objname="box_center" name="gyro_c"/>
    <framexaxis objtype="site" objname="box_center" name="xaxis_c"/>
  </sensor>
</mujoco>
